<?xml version="1.0"?>
<!--
   Aldebaran Robotics Romeo URDF model

   FIXME: fill missing data: sensors
  -->
<robot xmlns:xacro="http://ros.org/wiki/xacro" name="romeo">
  <link name="base_link"/>

  <link name="body">
    <inertial>
      <origin xyz="0.00932 0 -0.2119" rpy="0 0 0"/>
      <mass value="4.16277"/>
      <inertia ixx="0.241879" ixy="-6.88963e-05" ixz="0.00282915" iyy="0.238168" iyz="0.000306252" izz="0.0214739"/>
    </inertial>
    <visual>
      <origin xyz="0 0 0" rpy="0 0 0" />
      <geometry>
	<mesh filename="package://romeo_description/meshes/Waist.dae" />
      </geometry>
    </visual>
    <collision>
      <origin xyz="0 0 0" rpy="0 0 0" />
      <geometry>
	<mesh filename="package://romeo_description/meshes/Waist.dae" />
      </geometry>
    </collision>
  </link>

  <link name="torso">
    <inertial>
      <origin xyz="0.0023 0 -0.04854" rpy="0 0 0"/>
      <mass value="9.9216"/>
      <inertia ixx="0.129332" ixy="-0.000359651" ixz="0.00283888" iyy="0.126831" iyz="-0.00200843" izz="0.110627"/>
    </inertial>
    <visual>
      <origin xyz="0 0 0" rpy="0 0 0" />
      <geometry>
	<mesh filename="package://romeo_description/meshes/Torso.dae" />
      </geometry>
    </visual>
    <collision>
      <origin xyz="0 0 0" rpy="0 0 0" />
      <geometry>
	<mesh filename="package://romeo_description/meshes/Torso.dae" />
      </geometry>
    </collision>
  </link>

  <link name="NeckYawLink">
    <inertial>
      <origin xyz="0 0 -0.03074" rpy="0 0 0"/>
      <mass value="0.51016"/>
      <inertia ixx="0.00122159" ixy="-8.014e-08" ixz="1.145e-08" iyy="0.00124608" iyz="-1.84095e-06" izz="0.000187965"/>
    </inertial>
  </link>

  <link name="NeckPitchLink">
    <inertial>
      <origin xyz="-0.00472 0 0.04432" rpy="0 0 0"/>
      <mass value="0.23875"/>
      <inertia ixx="0.000866022" ixy="-1.57263e-06" ixz="6.13825e-05" iyy="0.000818287" iyz="9.69515e-06" izz="0.000238919"/>
    </inertial>
    <visual>
      <origin xyz="0 0 0" rpy="0 0 0" />
      <geometry>
	<mesh filename="package://romeo_description/meshes/NeckPitch.dae" />
      </geometry>
    </visual>
    <collision>
      <origin xyz="0 0 0" rpy="0 0 0" />
      <geometry>
	<mesh filename="package://romeo_description/meshes/NeckPitch.dae" />
      </geometry>
    </collision>
  </link>

  <link name="HeadPitchLink">
    <inertial>
      <origin xyz="0.00137 0 -0.00641" rpy="0 0 0"/>
      <mass value="0.13981"/>
      <inertia ixx="3.89601e-05" ixy="-3.814e-08" ixz="-2.29622e-06" iyy="7.25465e-05" iyz="-6.46e-09" izz="5.3765e-05"/>
    </inertial>
  </link>

  <link name="HeadRollLink">
    <inertial>
      <origin xyz="0.01617 0 0.00757" rpy="0 0 0"/>
      <mass value="1.41282"/>
      <inertia ixx="0.0149087" ixy="-5.14209e-05" ixz="-0.000684893" iyy="0.0173189" iyz="-0.000191527" izz="0.00735475"/>
    </inertial>
    <visual>
      <origin xyz="0 0 0" rpy="0 0 0" />
      <geometry>
	<mesh filename="package://romeo_description/meshes/HeadRoll.dae" />
      </geometry>
    </visual>
    <collision>
      <origin xyz="0 0 0" rpy="0 0 0" />
      <geometry>
	<mesh filename="package://romeo_description/meshes/HeadRoll.dae" />
      </geometry>
    </collision>
  </link>

  <link name="LShoulderPitchLink">
    <inertial>
      <origin xyz="0.00149 -0.03299 0.00018" rpy="0 0 0"/>
      <mass value="0.69402"/>
      <inertia ixx="0.00201004" ixy="2.37595e-06" ixz="-2.16793e-06" iyy="0.000570626" iyz="8.27832e-06" izz="0.00194068"/>
    </inertial>
  </link>

  <link name="LShoulderYawLink">
    <inertial>
      <origin xyz="0.09367 0.01373 0.00103" rpy="0 0 0"/>
      <mass value="0.57151"/>
      <inertia ixx="0.000742818" ixy="-0.000617675" ixz="-7.28438e-05" iyy="0.00650202" iyz="-1.25157e-05" izz="0.00664434"/>
    </inertial>
    <visual>
      <origin xyz="0 0 0" rpy="0 0 0" />
      <geometry>
	<mesh filename="package://romeo_description/meshes/LShoulderYaw.dae" />
      </geometry>
    </visual>
    <collision>
      <origin xyz="0 0 0" rpy="0 0 0" />
      <geometry>
	<mesh filename="package://romeo_description/meshes/LShoulderYaw.dae" />
      </geometry>
    </collision>
  </link>

  <link name="LElbowRollLink">
    <inertial>
      <origin xyz="-0.02231 -0.0024 0" rpy="0 0 0"/>
      <mass value="0.39848"/>
      <inertia ixx="0.000179003" ixy="-2.25555e-06" ixz="1.376e-08" iyy="0.000804322" iyz="8.007e-08" izz="0.00077956"/>
    </inertial>
  </link>

  <link name="LElbowYawLink">
    <inertial>
      <origin xyz="0.06738 0.01043 -0.00031" rpy="0 0 0"/>
      <mass value="0.31265"/>
      <inertia ixx="0.000375096" ixy="-0.000225283" ixz="2.58073e-06" iyy="0.00209728" iyz="2.74613e-06" izz="0.00211065"/>
    </inertial>
    <visual>
      <origin xyz="0 0 0" rpy="0 0 0" />
      <geometry>
	<mesh filename="package://romeo_description/meshes/LElbowYaw.dae" />
      </geometry>
    </visual>
    <collision>
      <origin xyz="0 0 0" rpy="0 0 0" />
      <geometry>
	<mesh filename="package://romeo_description/meshes/LElbowYaw.dae" />
      </geometry>
    </collision>
  </link>

  <link name="LWristRollLink">
    <inertial>
      <origin xyz="-0.0593 -5e-05 -0.00069" rpy="0 0 0"/>
      <mass value="0.17563"/>
      <inertia ixx="6.72145e-05" ixy="-6.373e-07" ixz="-1.35809e-05" iyy="0.000851196" iyz="-2.443e-08" izz="0.000840348"/>
    </inertial>
    <visual>
      <origin xyz="0 0 0" rpy="0 0 0" />
      <geometry>
	<mesh filename="package://romeo_description/meshes/LWristRoll.dae" />
      </geometry>
    </visual>
    <collision>
      <origin xyz="0 0 0" rpy="0 0 0" />
      <geometry>
	<mesh filename="package://romeo_description/meshes/LWristRoll.dae" />
      </geometry>
    </collision>
  </link>

  <link name="LWristYawLink">
    <inertial>
      <origin xyz="-0.00746 -0.00016 -0.00022" rpy="0 0 0"/>
      <mass value="0.07595"/>
      <inertia ixx="1.45402e-05" ixy="-4.157e-08" ixz="7.674e-08" iyy="3.91907e-05" iyz="3.08e-09" izz="3.81787e-05"/>
    </inertial>
    <visual>
      <origin xyz="0 0 0" rpy="0 0 0" />
      <geometry>
	<mesh filename="package://romeo_description/meshes/WristYaw.dae" />
      </geometry>
    </visual>
    <collision>
      <origin xyz="0 0 0" rpy="0 0 0" />
      <geometry>
	<mesh filename="package://romeo_description/meshes/WristYaw.dae" />
      </geometry>
    </collision>
  </link>

  <link name="l_wrist">
    <inertial>
      <origin xyz="0.06987 -0.00381 -0.00165" rpy="0 0 0"/>
      <mass value="0.16569"/>
      <inertia ixx="0.000112529" ixy="4.72583e-05" ixz="1.70404e-05" iyy="0.00107982" iyz="-1.54761e-05" izz="0.00115367"/>
    </inertial>
    <visual>
      <origin xyz="0 0 0" rpy="0 0 0" />
      <geometry>
	<mesh filename="package://romeo_description/meshes/LHand.dae" />
      </geometry>
    </visual>
    <collision>
      <origin xyz="0 0 0" rpy="0 0 0" />
      <geometry>
	<mesh filename="package://romeo_description/meshes/LHand.dae" />
      </geometry>
    </collision>
  </link>

  <link name="RShoulderPitchLink">
    <inertial>
      <origin xyz="0.00149 0.03299 0.00018" rpy="0 0 0"/>
      <mass value="0.69402"/>
      <inertia ixx="0.00201004" ixy="-2.37595e-06" ixz="2.16793e-06" iyy="0.000570626" iyz="8.27832e-06" izz="0.00194068"/>
    </inertial>
  </link>

  <link name="RShoulderYawLink">
    <inertial>
      <origin xyz="0.09367 -0.01373 0.00103" rpy="0 0 0"/>
      <mass value="0.57151"/>
      <inertia ixx="0.000742356" ixy="0.000617202" ixz="5.98521e-06" iyy="0.00649989" iyz="-1.07417e-06" izz="0.000664209"/>
    </inertial>
    <visual>
      <origin xyz="0 0 0" rpy="0 0 0" />
      <geometry>
	<mesh filename="package://romeo_description/meshes/RShoulderYaw.dae" />
      </geometry>
    </visual>
    <collision>
      <origin xyz="0 0 0" rpy="0 0 0" />
      <geometry>
	<mesh filename="package://romeo_description/meshes/RShoulderYaw.dae" />
      </geometry>
    </collision>
  </link>

  <link name="RElbowRollLink">
    <inertial>
      <origin xyz="-0.02231 0.0024 0" rpy="0 0 0"/>
      <mass value="0.39848"/>
      <inertia ixx="0.000179003" ixy="-2.25555e-06" ixz="1.376e-08" iyy="0.000804322" iyz="8.007e-08" izz="0.00077956"/>
    </inertial>
  </link>

  <link name="RElbowYawLink">
    <inertial>
      <origin xyz="0.06738 -0.01043 -0.00031" rpy="0 0 0"/>
      <mass value="0.31265"/>
      <inertia ixx="0.000366728" ixy="0.000185631" ixz="-5.37905e-07" iyy="0.00211104" iyz="3.1932e-07" izz="0.000211493"/>
    </inertial>
    <visual>
      <origin xyz="0 0 0" rpy="0 0 0" />
      <geometry>
	<mesh filename="package://romeo_description/meshes/RElbowYaw.dae" />
      </geometry>
    </visual>
    <collision>
      <origin xyz="0 0 0" rpy="0 0 0" />
      <geometry>
	<mesh filename="package://romeo_description/meshes/RElbowYaw.dae" />
      </geometry>
    </collision>
  </link>

  <link name="RWristRollLink">
    <inertial>
      <origin xyz="-0.0593 5e-05 -0.00069" rpy="0 0 0"/>
      <mass value="0.17563"/>
      <inertia ixx="6.72145e-05" ixy="-6.373e-07" ixz="-1.35809e-05" iyy="0.000851196" iyz="-2.443e-08" izz="0.000840348"/>
    </inertial>
    <visual>
      <origin xyz="0 0 0" rpy="0 0 0" />
      <geometry>
	<mesh filename="package://romeo_description/meshes/RWristRoll.dae" />
      </geometry>
    </visual>
    <collision>
      <origin xyz="0 0 0" rpy="0 0 0" />
      <geometry>
	<mesh filename="package://romeo_description/meshes/RWristRoll.dae" />
      </geometry>
    </collision>
  </link>

  <link name="RWristYawLink">
    <inertial>
      <origin xyz="-0.00746 0.00016 -0.00022" rpy="0 0 0"/>
      <mass value="0.07595"/>
      <inertia ixx="1.45402e-05" ixy="-4.157e-08" ixz="7.674e-08" iyy="3.91907e-05" iyz="3.08e-09" izz="3.81787e-05"/>
    </inertial>
    <visual>
      <origin xyz="0 0 0" rpy="0 0 0" />
      <geometry>
	<mesh filename="package://romeo_description/meshes/WristYaw.dae" />
      </geometry>
    </visual>
    <collision>
      <origin xyz="0 0 0" rpy="0 0 0" />
      <geometry>
	<mesh filename="package://romeo_description/meshes/WristYaw.dae" />
      </geometry>
    </collision>
  </link>

  <link name="r_wrist">
    <inertial>
      <origin xyz="0.06987 0.00381 -0.00165" rpy="0 0 0"/>
      <mass value="0.16569"/>
      <inertia ixx="0.000112529" ixy="0" ixz="0" iyy="0.00107982" iyz="0" izz="0.00115367"/>
    </inertial>
    <visual>
      <origin xyz="0 0 0" rpy="0 0 0" />
      <geometry>
	<mesh filename="package://romeo_description/meshes/RHand.dae" />
      </geometry>
    </visual>
    <collision>
      <origin xyz="0 0 0" rpy="0 0 0" />
      <geometry>
	<mesh filename="package://romeo_description/meshes/RHand.dae" />
      </geometry>
    </collision>
  </link>

  <link name="LHipYawLink">
    <inertial>
      <origin xyz="-0.00871 -0.00022 0.06319" rpy="0 0 0"/>
      <mass value="0.49477"/>
      <inertia ixx="0.00303668" ixy="-0" ixz="-0" iyy="0.00347998" iyz="-0" izz="0.000622773"/>
    </inertial>
  </link>

  <link name="LHipRollLink">
    <inertial>
      <origin xyz="0.00293 -0.00027 0.00011" rpy="0 0 0"/>
      <mass value="0.6607"/>
      <inertia ixx="0.00089862" ixy="0" ixz="0" iyy="0.000509559" iyz="0" izz="0.000935392"/>
    </inertial>
  </link>

  <link name="LHipPitchLink">
    <inertial>
      <origin xyz="-0.00971 0.00135 -0.15083" rpy="0 0 0"/>
      <mass value="4.33935"/>
      <inertia ixx="0.132895" ixy="0" ixz="0" iyy="0.133977" iyz="0" izz="0.0121687"/>
    </inertial>
    <visual>
      <origin xyz="0 0 0" rpy="0 0 0" />
      <geometry>
	<mesh filename="package://romeo_description/meshes/LHipPitch.dae" />
      </geometry>
    </visual>
    <collision>
      <origin xyz="0 0 0" rpy="0 0 0" />
      <geometry>
	<mesh filename="package://romeo_description/meshes/LHipPitch.dae" />
      </geometry>
    </collision>
  </link>

  <link name="LKneePitchLink">
    <inertial>
      <origin xyz="-0.00532 -0.00075 -0.12258" rpy="0 0 0"/>
      <mass value="2.61063"/>
      <inertia ixx="0.054913" ixy="0" ixz="0" iyy="0.0549663" iyz="0" izz="0.00398482"/>
    </inertial>
    <visual>
      <origin xyz="0 0 0" rpy="0 0 0" />
      <geometry>
	<mesh filename="package://romeo_description/meshes/LKneePitch.dae" />
      </geometry>
    </visual>
    <collision>
      <origin xyz="0 0 0" rpy="0 0 0" />
      <geometry>
	<mesh filename="package://romeo_description/meshes/LKneePitch.dae" />
      </geometry>
    </collision>
  </link>

  <link name="LAnklePitchLink">
    <inertial>
      <origin xyz="0.00059 0.00051 0.00038" rpy="0 0 0"/>
      <mass value="0.5008"/>
      <inertia ixx="0.000429952" ixy="0" ixz="0" iyy="0.000281451" iyz="0" izz="0.000527665"/>
    </inertial>
  </link>

  <link name="l_ankle">
    <inertial>
      <origin xyz="0.01872  0.00223  -0.03215" rpy="0 0 0"/>
      <mass value="0.74347"/>
      <inertia ixx="0.003507" ixy="0" ixz="0" iyy="0.016213" iyz="0" izz="0.014735"/>
    </inertial>
    <visual>
      <origin xyz="0 0 0" rpy="0 0 0" />
      <geometry>
	<mesh filename="package://romeo_description/meshes/LAnkleRoll.dae" />
      </geometry>
    </visual>
    <collision>
      <origin xyz="0 0 0" rpy="0 0 0" />
      <geometry>
	<mesh filename="package://romeo_description/meshes/LAnkleRoll.dae" />
      </geometry>
    </collision>
  </link>
  <link name="l_sole"/>

  <link name="l_toe">
    <inertial>
      <origin xyz="0.02067  -0.00198  -0.00964" rpy="0 0 0"/>
      <mass value="0.24032"/>
      <inertia ixx="0.000232177" ixy="0.000026659" ixz="-0.000059566" iyy="0.000296598" iyz="-0.000002851" izz="0.000427637" />
    </inertial>
    <visual>
      <origin xyz="0 0 0" rpy="0 0 0" />
      <geometry>
	<mesh filename="package://romeo_description/meshes/LToePitch.dae" />
      </geometry>
    </visual>
    <collision>
      <origin xyz="0 0 0" rpy="0 0 0" />
      <geometry>
	<mesh filename="package://romeo_description/meshes/LToePitch.dae" />
      </geometry>
    </collision>
  </link>

  <link name="RHipYawLink">
    <inertial>
      <origin xyz="-0.00871 0.00022 0.06319" rpy="0 0 0"/>
      <mass value="0.49477"/>
      <inertia ixx="0.00303668" ixy="0" ixz="0" iyy="0.00347998" iyz="0" izz="0.000622773"/>
    </inertial>
  </link>

  <link name="RHipRollLink">
    <inertial>
      <origin xyz="0.00293 0.00027 0.00011" rpy="0 0 0"/>
      <mass value="0.6607"/>
      <inertia ixx="0.00089862" ixy="0" ixz="0" iyy="0.000509559" iyz="0" izz="0.000935392"/>
    </inertial>
  </link>

  <link name="RHipPitchLink">
    <inertial>
      <origin xyz="-0.00971 -0.00135 -0.15083" rpy="0 0 0"/>
      <mass value="4.33935"/>
      <inertia ixx="0.132895" ixy="0" ixz="0" iyy="0.133977" iyz="0" izz="0.0121687"/>
    </inertial>
    <visual>
      <origin xyz="0 0 0" rpy="0 0 0"/>
      <geometry>
	<mesh filename="package://romeo_description/meshes/RHipPitch.dae"/>
      </geometry>
    </visual>
    <collision>
      <origin xyz="0 0 0" rpy="0 0 0" />
      <geometry>
	<mesh filename="package://romeo_description/meshes/RHipPitch.dae" />
      </geometry>
    </collision>
  </link>

  <link name="RKneePitchLink">
    <inertial>
      <origin xyz="-0.00532 0.00075 -0.12258" rpy="0 0 0"/>
      <mass value="2.61063"/>
      <inertia ixx="0.054913" ixy="0" ixz="0" iyy="0.0549663" iyz="0" izz="0.00398482"/>
    </inertial>
    <visual>
      <origin xyz="0 0 0" rpy="0 0 0" />
      <geometry>
	<mesh filename="package://romeo_description/meshes/RKneePitch.dae" />
      </geometry>
    </visual>
    <collision>
      <origin xyz="0 0 0" rpy="0 0 0" />
      <geometry>
	<mesh filename="package://romeo_description/meshes/RKneePitch.dae" />
      </geometry>
    </collision>
  </link>

  <link name="RAnklePitchLink">
    <inertial>
      <origin xyz="0.00059 -0.00051 0.00038" rpy="0 0 0"/>
      <mass value="0.5008"/>
      <inertia ixx="0.000429952" ixy="0" ixz="0" iyy="0.000281451" iyz="0" izz="0.000527665"/>
    </inertial>
  </link>

  <link name="r_ankle">
    <inertial>
      <origin xyz="0.01872  -0.00223  -0.03215" rpy="0 0 0"/>
      <mass value="0.74347"/>
      <inertia ixx="0.003507" ixy="0" ixz="0" iyy="0.016213" iyz="0" izz="0.014735"/>
    </inertial>
    <visual>
      <origin xyz="0 0 0" rpy="0 0 0" />
      <geometry>
	<mesh filename="package://romeo_description/meshes/RAnkleRoll.dae" />
      </geometry>
    </visual>
    <collision>
      <origin xyz="0 0 0" rpy="0 0 0" />
      <geometry>
	<mesh filename="package://romeo_description/meshes/RAnkleRoll.dae" />
      </geometry>
    </collision>
  </link>
  <link name="r_sole"/>

  <link name="r_toe">
    <inertial>
      <origin xyz="0.02067  -0.00198  -0.00964" rpy="0 0 0"/>
      <mass value="0.24032"/>
      <inertia ixx="0.000232177" ixy="0.000026659" ixz="-0.000059566" iyy="0.000296598" iyz="-0.000002851" izz="0.000427637" />
    </inertial>
    <visual>
      <origin xyz="0 0 0" rpy="0 0 0" />
      <geometry>
	<mesh filename="package://romeo_description/meshes/RToePitch.dae" />
      </geometry>
    </visual>
    <collision>
      <origin xyz="0 0 0" rpy="0 0 0" />
      <geometry>
	<mesh filename="package://romeo_description/meshes/RToePitch.dae" />
      </geometry>
    </collision>
  </link>



  <!--   Joints following below -->

  <joint name="waist" type="fixed">
    <parent link="base_link"/>
    <child link="body"/>
    <origin xyz="0 0 0" rpy="0 0 0"/>
  </joint>
  <joint name="TrunkYaw" type="revolute">
    <origin xyz="0 0 0.2" rpy="0 0 0"/>
    <axis xyz="0 0 1"/>
    <parent link="body"/>
    <child link="torso"/>
    <limit effort="80.902" lower="-0.785398" upper="0.785398" velocity="1.5"/>
  </joint>

  <joint name="NeckYaw" type="revolute">
    <origin xyz="0 0 0.0835" rpy="0 0 0"/>
    <axis xyz="0 0 1"/>
    <parent link="torso"/>
    <child link="NeckYawLink"/>
    <limit effort="3.662" lower="-1.5708" upper="1.5708" velocity="4"/>
  </joint>

  <joint name="NeckPitch" type="revolute">
    <origin xyz="0 0 0" rpy="0 0 0"/>
    <axis xyz="0 1 0"/>
    <parent link="NeckYawLink"/>
    <child link="NeckPitchLink"/>
    <limit effort="2.978" lower="-0.349066" upper="0.698132" velocity="2.2"/>
  </joint>

  <joint name="HeadPitch" type="revolute">
    <origin xyz="0 0 0.09511" rpy="0 0 0"/>
    <axis xyz="0 1 0"/>
    <parent link="NeckPitchLink"/>
    <child link="HeadPitchLink"/>
    <limit effort="2.57" lower="-0.349066" upper="0.279253" velocity="1.9"/>
  </joint>

  <joint name="HeadRoll" type="revolute">
    <origin xyz="0 0 0" rpy="0 0 0"/>
    <axis xyz="1 0 0"/>
    <parent link="HeadPitchLink"/>
    <child link="HeadRollLink"/>
    <limit effort="0.9" lower="-0.349066" upper="0.349066" velocity="1.5"/>
  </joint>

  <joint name="LShoulderPitch" type="revolute">
    <origin xyz="0.005 0.19 0" rpy="-0.158879 -0.0725189 -0.424682"/>
    <axis xyz="0 1 0"/>
    <parent link="torso"/>
    <child link="LShoulderPitchLink"/>
    <limit effort="19.095" lower="-1.44478" upper="2.22041" velocity="2.2"/>
  </joint>

  <joint name="LShoulderYaw" type="revolute">
    <origin xyz="0 0 0" rpy="0 0 0.430457"/>
    <axis xyz="0 0 1"/>
    <parent link="LShoulderPitchLink"/>
    <child link="LShoulderYawLink"/>
    <limit effort="9.031" lower="-0.430472" upper="1.14032" velocity="4"/>
  </joint>

  <joint name="LElbowRoll" type="revolute">
    <origin xyz="0.205 0 0" rpy="0.17452 -0 0"/>
    <axis xyz="1 0 0"/>
    <parent link="LShoulderYawLink"/>
    <child link="LElbowRollLink"/>
    <limit effort="7.404" lower="-2.0944" upper="2.0944" velocity="3.7"/>
  </joint>

  <joint name="LElbowYaw" type="revolute">
    <origin xyz="0 0 0" rpy="0 0 0"/>
    <axis xyz="0 0 1"/>
    <parent link="LElbowRollLink"/>
    <child link="LElbowYawLink"/>
    <limit effort="6.02" lower="-1.5708" upper="0" velocity="4"/>
  </joint>

  <joint name="LWristRoll" type="revolute">
    <origin xyz="0.1823 0 0" rpy="0 0 0"/>
    <axis xyz="1 0 0"/>
    <parent link="LElbowYawLink"/>
    <child link="LWristRollLink"/>
    <limit effort="2.177" lower="-3.66519" upper="0.523599" velocity="1.1"/>
  </joint>

  <joint name="LWristYaw" type="revolute">
    <origin xyz="0 0 0" rpy="0 0 0"/>
    <axis xyz="0 0 1"/>
    <parent link="LWristRollLink"/>
    <child link="LWristYawLink"/>
    <limit effort="0.862" lower="-0.436332" upper="0.436332" velocity="2.26"/>
  </joint>

  <joint name="LWristPitch" type="revolute">
    <origin xyz="0 0 0" rpy="0 0 0"/>
    <axis xyz="0 1 0"/>
    <parent link="LWristYawLink"/>
    <child link="l_wrist"/>
    <limit effort="0.6" lower="-0.977384" upper="0.977384" velocity="3.75"/>
  </joint>

  <joint name="RShoulderPitch" type="revolute">
    <origin xyz="0.005 -0.19 0" rpy="0.158879 -0.0725189 0.424682"/>
    <axis xyz="0 1 0"/>
    <parent link="torso"/>
    <child link="RShoulderPitchLink"/>
    <limit effort="19.095" lower="-1.44478" upper="2.22041" velocity="2.2"/>
  </joint>

  <joint name="RShoulderYaw" type="revolute">
    <origin xyz="0 0 0" rpy="-0 -0 -0.430457"/>
    <axis xyz="0 0 1"/>
    <parent link="RShoulderPitchLink"/>
    <child link="RShoulderYawLink"/>
    <limit effort="9.031" lower="-1.14032" upper="0.430472" velocity="4"/>
  </joint>

  <joint name="RElbowRoll" type="revolute">
    <origin xyz="0.205 0 0" rpy="-0.17452 -0 0"/>
    <axis xyz="1 0 0"/>
    <parent link="RShoulderYawLink"/>
    <child link="RElbowRollLink"/>
    <limit effort="7.404" lower="-2.0944" upper="2.0944" velocity="3.7"/>
  </joint>

  <joint name="RElbowYaw" type="revolute">
    <origin xyz="0 0 0" rpy="0 0 0"/>
    <axis xyz="0 0 1"/>
    <parent link="RElbowRollLink"/>
    <child link="RElbowYawLink"/>
    <limit effort="6.02" lower="0" upper="1.5708" velocity="4"/>
  </joint>

  <joint name="RWristRoll" type="revolute">
    <origin xyz="0.1823 0 0" rpy="0 0 0"/>
    <axis xyz="1 0 0"/>
    <parent link="RElbowYawLink"/>
    <child link="RWristRollLink"/>
    <limit effort="2.177" lower="-0.523599" upper="3.66519" velocity="1.1"/>
  </joint>

  <joint name="RWristYaw" type="revolute">
    <origin xyz="0 0 0" rpy="0 0 0"/>
    <axis xyz="0 0 1"/>
    <parent link="RWristRollLink"/>
    <child link="RWristYawLink"/>
    <limit effort="0.862" lower="-0.436332" upper="0.436332" velocity="2.26"/>
  </joint>

  <joint name="RWristPitch" type="revolute">
    <origin xyz="0 0 0" rpy="0 0 0"/>
    <axis xyz="0 1 0"/>
    <parent link="RWristYawLink"/>
    <child link="r_wrist"/>
    <limit effort="0.6" lower="-0.977384" upper="0.977384" velocity="3.75"/>
  </joint>

  <joint name="LHipYaw" type="revolute">
    <origin xyz="0 0.096 -0.20004" rpy="0 0 0"/>
    <axis xyz="0 0 1"/>
    <parent link="body"/>
    <child link="LHipYawLink"/>
    <limit effort="9.2" lower="-0.261799" upper="0.261799" velocity="0.32"/>
  </joint>

  <joint name="LHipRoll" type="revolute">
    <origin xyz="0 0 0" rpy="0 0 0"/>
    <axis xyz="1 0 0"/>
    <parent link="LHipYawLink"/>
    <child link="LHipRollLink"/>
    <limit effort="46.6" lower="-0.261799" upper="0.523599" velocity="2.09"/>
  </joint>

  <joint name="LHipPitch" type="revolute">
    <origin xyz="0 0 0" rpy="0 0 0"/>
    <axis xyz="0 1 0"/>
    <parent link="LHipRollLink"/>
    <child link="LHipPitchLink"/>
    <limit effort="46.6" lower="-1.71042" upper="0.401426" velocity="2.09"/>
  </joint>

  <joint name="LKneePitch" type="revolute">
    <origin xyz="0 0 -0.32" rpy="0 0 0"/>
    <axis xyz="0 1 0"/>
    <parent link="LHipPitchLink"/>
    <child link="LKneePitchLink"/>
    <limit effort="38.17" lower="0" upper="2.00713" velocity="6"/>
  </joint>

  <joint name="LAnklePitch" type="revolute">
    <origin xyz="0 0 -0.29" rpy="0 0 0"/>
    <axis xyz="0 1 0"/>
    <parent link="LKneePitchLink"/>
    <child link="LAnklePitchLink"/>
    <limit effort="25.76" lower="-0.523599" upper="0.785398" velocity="2.1"/>
  </joint>

  <joint name="LAnkleRoll" type="revolute">
    <origin xyz="0 0 0" rpy="0 0 0"/>
    <axis xyz="1 0 0"/>
    <parent link="LAnklePitchLink"/>
    <child link="l_ankle"/>
    <limit effort="25.76" lower="-0.349066" upper="0.349066" velocity="2.1"/>
  </joint>

  <joint name="LToePitch" type="revolute">
    <origin xyz="0.1135 0 -0.0524" rpy="0 0 0"/>
    <axis xyz="0 1 0"/>
    <parent link="l_ankle"/>
    <child link="l_toe"/>
    <limit effort="0" lower="-0.78539815" upper="0" velocity="0" />
  </joint>

  <joint name="RHipYaw" type="revolute">
    <origin xyz="0 -0.096 -0.20004" rpy="0 0 0"/>
    <axis xyz="0 0 1"/>
    <parent link="body"/>
    <child link="RHipYawLink"/>
    <limit effort="9.2" lower="-0.261799" upper="0.261799" velocity="0.32"/>
  </joint>

  <joint name="RHipRoll" type="revolute">
    <origin xyz="0 0 0" rpy="0 0 0"/>
    <axis xyz="1 0 0"/>
    <parent link="RHipYawLink"/>
    <child link="RHipRollLink"/>
    <limit effort="46.6" lower="-0.523599" upper="0.261799" velocity="2.09"/>
  </joint>

  <joint name="RHipPitch" type="revolute">
    <origin xyz="0 0 0" rpy="0 0 0"/>
    <axis xyz="0 1 0"/>
    <parent link="RHipRollLink"/>
    <child link="RHipPitchLink"/>
    <limit effort="46.6" lower="-1.71042" upper="0.401426" velocity="2.09"/>
  </joint>

  <joint name="RKneePitch" type="revolute">
    <origin xyz="0 0 -0.32" rpy="0 0 0"/>
    <axis xyz="0 1 0"/>
    <parent link="RHipPitchLink"/>
    <child link="RKneePitchLink"/>
    <limit effort="38.17" lower="0" upper="2.00713" velocity="6"/>
  </joint>

  <joint name="RAnklePitch" type="revolute">
    <origin xyz="0 0 -0.29" rpy="0 0 0"/>
    <axis xyz="0 1 0"/>
    <parent link="RKneePitchLink"/>
    <child link="RAnklePitchLink"/>
    <limit effort="25.76" lower="-0.523599" upper="0.785398" velocity="2.1"/>
  </joint>

  <joint name="RAnkleRoll" type="revolute">
    <origin xyz="0 0 0" rpy="0 0 0"/>
    <axis xyz="1 0 0"/>
    <parent link="RAnklePitchLink"/>
    <child link="r_ankle"/>
    <limit effort="25.76" lower="-0.349066" upper="0.349066" velocity="2.1"/>
  </joint>

  <joint name="RToePitch" type="revolute">
    <origin xyz="0.1135 0 -0.0524" rpy="0 0 0"/>
    <axis xyz="0 1 0"/>
    <parent link="r_ankle"/>
    <child link="r_toe"/>
    <limit effort="0" lower="-0.78539815" upper="0" velocity="0" />
  </joint>

  <joint name="l_sole_joint" type="fixed">
    <parent link="l_ankle"/>
    <child link="l_sole"/>
    <origin xyz="0 0 -0.067" rpy="0 0 0"/>
  </joint>
  <joint name="r_sole_joint" type="fixed">
    <parent link="r_ankle"/>
    <child link="r_sole"/>
    <origin xyz="0 0 -0.067" rpy="0 0 0"/>
  </joint>

  <!-- Humanoid standard frame: gaze -->
  <joint name="gaze_joint" type="fixed">
    <parent link="HeadRollLink"/>
    <child link="gaze"/>
    <origin xyz="0.09178 0 0.05425" rpy="0 0 0" />
  </joint>
  <link name="gaze"/>

  <!-- Sensors: cameras -->
  <joint name="LEyeYaw" type="revolute">
    <origin xyz="0 0.03192 0" rpy="0 0 0"/>
    <axis xyz="0 0 1"/>
    <parent link="gaze"/>
    <child link="LEyeYawLink"/>
    <limit effort="0.01752" lower="-0.523599" upper="0.523599" velocity="293.215"/>
  </joint>
  <link name="LEyeYawLink"/>

  <joint name="LEyePitch" type="revolute">
    <origin xyz="0 0 0" rpy="0 0 0"/>
    <axis xyz="0 1 0"/>
    <parent link="LEyeYawLink"/>
    <child link="CameraLeftEye"/>
    <limit effort="0.01752" lower="-0.349066" upper="0.349066" velocity="293.215"/>
  </joint>
  <link name="CameraLeftEye"/>

  <joint name="REyeYaw" type="revolute">
    <origin xyz="0 -0.03192 0" rpy="0 0 0"/>
    <axis xyz="0 0 1"/>
    <parent link="gaze"/>
    <child link="REyeYawLink"/>
    <limit effort="0.01752" lower="-0.523599" upper="0.523599" velocity="293.215"/>
  </joint>
  <link name="REyeYawLink"/>

  <joint name="REyePitch" type="revolute">
    <origin xyz="0 0 0" rpy="0 0 0"/>
    <axis xyz="0 1 0"/>
    <parent link="REyeYawLink"/>
    <child link="CameraRightEye"/>
    <limit effort="0.01752" lower="-0.349066" upper="0.349066" velocity="293.215"/>
  </joint>
  <link name="CameraRightEye"/>

  <joint name="CameraLeft_joint" type="fixed">
    <origin xyz="-0.0021 0.055 0.0333" rpy="0 0 0" />
    <parent link="gaze"/>
    <child link="CameraLeft"/>
  </joint>
  <link name="CameraLeft"/>

  <joint name="CameraRight_joint" type="fixed">
    <origin xyz="-0.0021 -0.055 0.0333" rpy="0 0 0" />
    <parent link="gaze"/>
    <child link="CameraRight"/>
  </joint>
  <link name="CameraRight"/>


  <!--
     Humanoid standard frames

     This section defines anchor joint renaming to respect the
     REP 120 (http://www.ros.org/reps/rep-0120.html):
     Coordinate Frames for Humanoids Robots
    -->

  <!-- Humanoid standard frames: wrists and hands -->
  <joint name="l_gripper_joint" type="fixed">
    <parent link="l_wrist"/>
    <child link="l_gripper"/>
    <origin xyz="0.09 0 -0.02" rpy="-1.57079633 0 0"/>
  </joint>
  <link name="l_gripper"/>

  <joint name="r_gripper_joint" type="fixed">
    <parent link="r_wrist"/>
    <child link="r_gripper"/>
    <origin xyz="0.09 0 -0.02" rpy="-1.57079633 0 0"/>
  </joint>
  <link name="r_gripper"/>
</robot>
